Workbook

Sheet Resumen
A1: Resumen General
A3: Tabla 1: Tiempo Promedio (s) por Tamaño | I3: m | J3: BST | K3: RB
A4: m | B4: BST (s) | C4: RedBlackBST (s) | D4: Ratio BST/RB | E4: log2(ratio BST) | F4: log2(ratio RB) | I4: 4096 | J4: =Inv_4096!B69 -> 0.0014793413 | K4: =Inv_4096!C69 -> 0.0014816003
A5: 4096 | B5: =Inv_4096!B69 -> 0.0014793413 | C5: =Inv_4096!C69 -> 0.0014816003 | D5: =B5/C5 -> 0.9984753 | E5: - | F5: - | I5: 8192 | J5: =Inv_8192!B69 -> 0.0023994776 | K5: =Inv_8192!C69 -> 0.0025812193
A6: 8192 | B6: =Inv_8192!B69 -> 0.0023994776 | C6: =Inv_8192!C69 -> 0.0025812193 | D6: =B6/C6 -> 0.92959074 | E6: =LOG(B6/B5,2) -> 0.69776544 | F6: =LOG(C6/C5,2) -> 0.80089647 | I6: 16384 | J6: =Inv_16384!B69 -> 0.0045460771 | K6: =Inv_16384!C69 -> 0.0047395519
A7: 16384 | B7: =Inv_16384!B69 -> 0.0045460771 | C7: =Inv_16384!C69 -> 0.0047395519 | D7: =B7/C7 -> 0.95917867 | E7: =LOG(B7/B6,2) -> 0.9219018 | F7: =LOG(C7/C6,2) -> 0.87669792 | I7: 32768 | J7: =Inv_32768!B69 -> 0.0098798765 | K7: =Inv_32768!C69 -> 0.0094746326
A8: 32768 | B8: =Inv_32768!B69 -> 0.0098798765 | C8: =Inv_32768!C69 -> 0.0094746326 | D8: =B8/C8 -> 1.0427715 | E8: =LOG(B8/B7,2) -> 1.1198709 | F8: =LOG(C8/C7,2) -> 0.99931935 | I8: 65536 | J8: =Inv_65536!B69 -> 0.022522212 | K8: =Inv_65536!C69 -> 0.021981787
A9: 65536 | B9: =Inv_65536!B69 -> 0.022522212 | C9: =Inv_65536!C69 -> 0.021981787 | D9: =B9/C9 -> 1.0245851 | E9: =LOG(B9/B8,2) -> 1.1887836 | F9: =LOG(C9/C8,2) -> 1.2141668 | I9: 131072 | J9: =Inv_131072!B69 -> 0.054662437 | K9: =Inv_131072!C69 -> 0.052242052
A10: 131072 | B10: =Inv_131072!B69 -> 0.054662437 | C10: =Inv_131072!C69 -> 0.052242052 | D10: =B10/C10 -> 1.0463302 | E10: =LOG(B10/B9,2) -> 1.2792012 | F10: =LOG(C10/C9,2) -> 1.2489029 | I10: 262144 | J10: =Inv_262144!B69 -> 0.13323365 | K10: =Inv_262144!C69 -> 0.13174957
A11: 262144 | B11: =Inv_262144!B69 -> 0.13323365 | C11: =Inv_262144!C69 -> 0.13174957 | D11: =B11/C11 -> 1.0112644 | E11: =LOG(B11/B10,2) -> 1.2853368 | F11: =LOG(C11/C10,2) -> 1.3345148 | I11: 524288 | J11: =Inv_524288!B69 -> 0.32775229 | K11: =Inv_524288!C69 -> 0.33107444
A12: 524288 | B12: =Inv_524288!B69 -> 0.32775229 | C12: =Inv_524288!C69 -> 0.33107444 | D12: =B12/C12 -> 0.98996554 | E12: =LOG(B12/B11,2) -> 1.2986473 | F12: =LOG(C12/C11,2) -> 1.3293574
A14: Tabla 2: Altura Promedio del Árbol
A15: m | B15: BST altura | C15: RedBlackBST altura | D15: Ratio h_BST/h_RB
A16: 4096 | B16: =Inv_4096!B72 -> 21.833333 | C16: =Inv_4096!C72 -> 13.166667 | D16: =B16/C16 -> 1.6582278
A17: 8192 | B17: =Inv_8192!B72 -> 23.566667 | C17: =Inv_8192!C72 -> 14.7 | D17: =B17/C17 -> 1.6031746
A18: 16384 | B18: =Inv_16384!B72 -> 27.8 | C18: =Inv_16384!C72 -> 16.033333 | D18: =B18/C18 -> 1.7338877
A19: 32768 | B19: =Inv_32768!B72 -> 30.166667 | C19: =Inv_32768!C72 -> 17.566667 | D19: =B19/C19 -> 1.7172676
A20: 65536 | B20: =Inv_65536!B72 -> 32.833333 | C20: =Inv_65536!C72 -> 19.2 | D20: =B20/C20 -> 1.7100694
A21: 131072 | B21: =Inv_131072!B72 -> 36.233333 | C21: =Inv_131072!C72 -> 20.533333 | D21: =B21/C21 -> 1.7646104
A22: 262144 | B22: =Inv_262144!B72 -> 38.933333 | C22: =Inv_262144!C72 -> 22.033333 | D22: =B22/C22 -> 1.7670197
A23: 524288 | B23: =Inv_524288!B72 -> 41.133333 | C23: =Inv_524288!C72 -> 23.466667 | D23: =B23/C23 -> 1.7528409
A25: Tabla 3: Promedio de Operaciones Exitosas y Fallidas
A26: m | B26: BST query_ok | C26: RB query_ok | D26: BST query_fail | E26: RB query_fail | F26: BST lend_ok | G26: RB lend_ok | H26: BST lend_fail
A27: 4096 | B27: =AVERAGE(Inv_4096!I3:I32) -> 53.933333 | C27: =AVERAGE(Inv_4096!I33:I62) -> 53.933333 | D27: =AVERAGE(Inv_4096!J3:J32) -> 1183.7333 | E27: =AVERAGE(Inv_4096!J33:J62) -> 1183.7333 | F27: =AVERAGE(Inv_4096!K3:K32) -> 22.833333 | G27: =AVERAGE(Inv_4096!K33:K62) -> 22.833333 | H27: =AVERAGE(Inv_4096!L3:L32) -> 593
A28: 8192 | B28: =AVERAGE(Inv_8192!I3:I32) -> 107 | C28: =AVERAGE(Inv_8192!I33:I62) -> 107 | D28: =AVERAGE(Inv_8192!J3:J32) -> 2356.1333 | E28: =AVERAGE(Inv_8192!J33:J62) -> 2356.1333 | F28: =AVERAGE(Inv_8192!K3:K32) -> 50.066667 | G28: =AVERAGE(Inv_8192!K33:K62) -> 50.066667 | H28: =AVERAGE(Inv_8192!L3:L32) -> 1180.5667
A29: 16384 | B29: =AVERAGE(Inv_16384!I3:I32) -> 212.13333 | C29: =AVERAGE(Inv_16384!I33:I62) -> 212.13333 | D29: =AVERAGE(Inv_16384!J3:J32) -> 4699.1667 | E29: =AVERAGE(Inv_16384!J33:J62) -> 4699.1667 | F29: =AVERAGE(Inv_16384!K3:K32) -> 95 | G29: =AVERAGE(Inv_16384!K33:K62) -> 95 | H29: =AVERAGE(Inv_16384!L3:L32) -> 2372.0667
A30: 32768 | B30: =AVERAGE(Inv_32768!I3:I32) -> 416.03333 | C30: =AVERAGE(Inv_32768!I33:I62) -> 416.03333 | D30: =AVERAGE(Inv_32768!J3:J32) -> 9439.8 | E30: =AVERAGE(Inv_32768!J33:J62) -> 9439.8 | F30: =AVERAGE(Inv_32768!K3:K32) -> 185.03333 | G30: =AVERAGE(Inv_32768!K33:K62) -> 185.03333 | H30: =AVERAGE(Inv_32768!L3:L32) -> 4708.4
A31: 65536 | B31: =AVERAGE(Inv_65536!I3:I32) -> 825.56667 | C31: =AVERAGE(Inv_65536!I33:I62) -> 825.56667 | D31: =AVERAGE(Inv_65536!J3:J32) -> 18829.733 | E31: =AVERAGE(Inv_65536!J33:J62) -> 18829.733 | F31: =AVERAGE(Inv_65536!K3:K32) -> 369.56667 | G31: =AVERAGE(Inv_65536!K33:K62) -> 369.56667 | H31: =AVERAGE(Inv_65536!L3:L32) -> 9470.9667
A32: 131072 | B32: =AVERAGE(Inv_131072!I3:I32) -> 1649.6333 | C32: =AVERAGE(Inv_131072!I33:I62) -> 1649.6333 | D32: =AVERAGE(Inv_131072!J3:J32) -> 37680.567 | E32: =AVERAGE(Inv_131072!J33:J62) -> 37680.567 | F32: =AVERAGE(Inv_131072!K3:K32) -> 757.03333 | G32: =AVERAGE(Inv_131072!K33:K62) -> 757.03333 | H32: =AVERAGE(Inv_131072!L3:L32) -> 18902.867
A33: 262144 | B33: =AVERAGE(Inv_262144!I3:I32) -> 3309.9333 | C33: =AVERAGE(Inv_262144!I33:I62) -> 3309.9333 | D33: =AVERAGE(Inv_262144!J3:J32) -> 75305.967 | E33: =AVERAGE(Inv_262144!J33:J62) -> 75305.967 | F33: =AVERAGE(Inv_262144!K3:K32) -> 1508.3 | G33: =AVERAGE(Inv_262144!K33:K62) -> 1508.3 | H33: =AVERAGE(Inv_262144!L3:L32) -> 37809.733
A34: 524288 | B34: =AVERAGE(Inv_524288!I3:I32) -> 6610.4 | C34: =AVERAGE(Inv_524288!I33:I62) -> 6610.4 | D34: =AVERAGE(Inv_524288!J3:J32) -> 150680.6 | E34: =AVERAGE(Inv_524288!J33:J62) -> 150680.6 | F34: =AVERAGE(Inv_524288!K3:K32) -> 2971.8 | G34: =AVERAGE(Inv_524288!K33:K62) -> 2971.8 | H34: =AVERAGE(Inv_524288!L3:L32) -> 75694.133
I58: m | J58: BST h | K58: RB h
I59: 4096 | J59: =Inv_4096!B72 -> 21.833333 | K59: =Inv_4096!C72 -> 13.166667
I60: 8192 | J60: =Inv_8192!B72 -> 23.566667 | K60: =Inv_8192!C72 -> 14.7
I61: 16384 | J61: =Inv_16384!B72 -> 27.8 | K61: =Inv_16384!C72 -> 16.033333
I62: 32768 | J62: =Inv_32768!B72 -> 30.166667 | K62: =Inv_32768!C72 -> 17.566667
I63: 65536 | J63: =Inv_65536!B72 -> 32.833333 | K63: =Inv_65536!C72 -> 19.2
I64: 131072 | J64: =Inv_131072!B72 -> 36.233333 | K64: =Inv_131072!C72 -> 20.533333
I65: 262144 | J65: =Inv_262144!B72 -> 38.933333 | K65: =Inv_262144!C72 -> 22.033333
I66: 524288 | J66: =Inv_524288!B72 -> 41.133333 | K66: =Inv_524288!C72 -> 23.466667
...

Sheet Inv_4096
A1: Experimento de Inventario — m = 4096
A2: instancia | B2: estructura | C2: m | D2: purchase_total | E2: query_total | F2: lend_total | G2: receive_total | H2: dispose_total | I2: query_successful | J2: query_failed | K2: lend_successful | L2: lend_failed | M2: receive_successful | N2: receive_failed | O2: final_size | P2: final_height | Q2: elapsed_seconds
A3: 1 | B3: BST | C3: 4096 | D3: 1413 | E3: 1208 | F3: 648 | G3: 418 | H3: 409 | I3: 61 | J3: 1147 | K3: 21 | L3: 627 | M3: 0 | N3: 418 | O3: 1335 | P3: 23 | Q3: 0.009086497
A4: 2 | B4: BST | C4: 4096 | D4: 1430 | E4: 1250 | F4: 597 | G4: 418 | H4: 401 | I4: 56 | J4: 1194 | K4: 21 | L4: 576 | M4: 0 | N4: 418 | O4: 1336 | P4: 21 | Q4: 0.001970591
A5: 3 | B5: BST | C5: 4096 | D5: 1447 | E5: 1226 | F5: 613 | G5: 399 | H5: 411 | I5: 61 | J5: 1165 | K5: 25 | L5: 588 | M5: 0 | N5: 399 | O5: 1373 | P5: 22 | Q5: 0.001852486
A6: 4 | B6: BST | C6: 4096 | D6: 1413 | E6: 1235 | F6: 614 | G6: 432 | H6: 402 | I6: 57 | J6: 1178 | K6: 20 | L6: 594 | M6: 0 | N6: 432 | O6: 1342 | P6: 20 | Q6: 0.001810462
A7: 5 | B7: BST | C7: 4096 | D7: 1444 | E7: 1242 | F7: 604 | G7: 404 | H7: 402 | I7: 49 | J7: 1193 | K7: 16 | L7: 588 | M7: 0 | N7: 404 | O7: 1369 | P7: 21 | Q7: 0.001724695
A8: 6 | B8: BST | C8: 4096 | D8: 1455 | E8: 1225 | F8: 628 | G8: 370 | H8: 418 | I8: 49 | J8: 1176 | K8: 20 | L8: 608 | M8: 0 | N8: 370 | O8: 1363 | P8: 25 | Q8: 0.001820789
A9: 7 | B9: BST | C9: 4096 | D9: 1395 | E9: 1234 | F9: 666 | G9: 391 | H9: 410 | I9: 43 | J9: 1191 | K9: 25 | L9: 641 | M9: 0 | N9: 391 | O9: 1320 | P9: 22 | Q9: 0.001860718
A10: 8 | B10: BST | C10: 4096 | D10: 1470 | E10: 1220 | F10: 613 | G10: 418 | H10: 375 | I10: 70 | J10: 1150 | K10: 25 | L10: 588 | M10: 0 | N10: 418 | O10: 1385 | P10: 21 | Q10: 0.001758507
A11: 9 | B11: BST | C11: 4096 | D11: 1427 | E11: 1253 | F11: 628 | G11: 379 | H11: 409 | I11: 53 | J11: 1200 | K11: 19 | L11: 609 | M11: 0 | N11: 379 | O11: 1362 | P11: 21 | Q11: 0.001093392
A12: 10 | B12: BST | C12: 4096 | D12: 1432 | E12: 1245 | F12: 635 | G12: 421 | H12: 363 | I12: 59 | J12: 1186 | K12: 20 | L12: 615 | M12: 0 | N12: 421 | O12: 1372 | P12: 21 | Q12: 0.001048715
A13: 11 | B13: BST | C13: 4096 | D13: 1487 | E13: 1200 | F13: 593 | G13: 401 | H13: 415 | I13: 62 | J13: 1138 | K13: 21 | L13: 572 | M13: 0 | N13: 401 | O13: 1409 | P13: 20 | Q13: 0.000989676
A14: 12 | B14: BST | C14: 4096 | D14: 1473 | E14: 1221 | F14: 637 | G14: 398 | H14: 367 | I14: 58 | J14: 1163 | K14: 30 | L14: 607 | M14: 0 | N14: 398 | O14: 1385 | P14: 22 | Q14: 0.000912242
... A62: 30 | B62: RedBlackBST | C62: 4096 | D62: 1464 | E62: 1224 | F62: 577 | G62: 420 | H62: 411 | I62: 52 | J62: 1172 | K62: 27 | L62: 550 | M62: 0 | N62: 420 | O62: 1391 | P62: 13 | Q62: 0.001124616
A65: Estadísticas
A66: Métrica | B66: BST | C66: RedBlackBST
A67: Mínimo (s) | B67: =MIN(Q3:Q32) -> 0.000838643 | C67: =MIN(Q33:Q62) -> 0.000895287
A68: Máximo (s) | B68: =MAX(Q3:Q32) -> 0.009086497 | C68: =MAX(Q33:Q62) -> 0.005896879
A69: Promedio (s) | B69: =AVERAGE(Q3:Q32) -> 0.0014793413 | C69: =AVERAGE(Q33:Q62) -> 0.0014816003
A70: Desv. Estándar | B70: =STDEV(Q3:Q32) -> 0.0014808439 | C70: =STDEV(Q33:Q62) -> 0.00098393568
A71: Coef. Variación | B71: =B70/B69 -> 1.0010157 | C71: =C70/C69 -> 0.66410333
A72: Altura Promedio | B72: =AVERAGE(P3:P32) -> 21.833333 | C72: =AVERAGE(P33:P62) -> 13.166667
A73: Altura Máxima | B73: =MAX(P3:P32) -> 25 | C73: =MAX(P33:P62) -> 15
A76: Histograma — BST | B76: Frecuencia
A77: 0.0006644–0.0015024 | B77: 22
A78: 0.0015024–0.0023404 | B78: 7
A79: 0.0023404–0.0031784 | B79: 0
A80: 0.0031784–0.0040164 | B80: 0
A81: 0.0040164–0.0048544 | B81: 0
A82: 0.0048544–0.0056925 | B82: 0
A83: 0.0056925–0.0065305 | B83: 1
A86: Histograma — RedBlackBST | B86: Frecuencia
A87: 0.0009071–0.0020109 | B87: 26
A88: 0.0020109–0.0031147 | B88: 3
A89: 0.0031147–0.0042185 | B89: 0
A90: 0.0042185–0.0053223 | B90: 0
A91: 0.0053223–0.0064261 | B91: 0
A92: 0.0064261–0.0075299 | B92: 0
A93: 0.0075299–0.0086337 | B93: 1

Sheet Inv_8192
A1: Experimento de Inventario — m = 8192
A2: instancia | B2: estructura | C2: m | D2: purchase_total | E2: query_total | F2: lend_total | G2: receive_total | H2: dispose_total | I2: query_successful | J2: query_failed | K2: lend_successful | L2: lend_failed | M2: receive_successful | N2: receive_failed | O2: final_size | P2: final_height | Q2: elapsed_seconds
A3: 1 | B3: BST | C3: 8192 | D3: 2844 | E3: 2458 | F3: 1250 | G3: 819 | H3: 821 | I3: 104 | J3: 2354 | K3: 53 | L3: 1197 | M3: 0 | N3: 819 | O3: 2691 | P3: 22 | Q3: 0.002231938
A4: 2 | B4: BST | C4: 8192 | D4: 2826 | E4: 2487 | F4: 1232 | G4: 830 | H4: 817 | I4: 116 | J4: 2371 | K4: 56 | L4: 1176 | M4: 0 | N4: 830 | O4: 2680 | P4: 23 | Q4: 0.002430523
A5: 3 | B5: BST | C5: 8192 | D5: 2818 | E5: 2465 | F5: 1246 | G5: 824 | H5: 839 | I5: 108 | J5: 2357 | K5: 52 | L5: 1194 | M5: 0 | N5: 824 | O5: 2647 | P5: 25 | Q5: 0.002478643
A6: 4 | B6: BST | C6: 8192 | D6: 2885 | E6: 2435 | F6: 1248 | G6: 812 | H6: 812 | I6: 110 | J6: 2325 | K6: 40 | L6: 1208 | M6: 0 | N6: 812 | O6: 2730 | P6: 24 | Q6: 0.002345418
A7: 5 | B7: BST | C7: 8192 | D7: 2860 | E7: 2426 | F7: 1275 | G7: 825 | H7: 806 | I7: 93 | J7: 2333 | K7: 49 | L7: 1226 | M7: 0 | N7: 825 | O7: 2701 | P7: 25 | Q7: 0.002517793
A8: 6 | B8: BST | C8: 8192 | D8: 2840 | E8: 2569 | F8: 1203 | G8: 736 | H8: 844 | I8: 105 | J8: 2464 | K8: 44 | L8: 1159 | M8: 0 | N8: 736 | O8: 2685 | P8: 25 | Q8: 0.002315991
A9: 7 | B9: BST | C9: 8192 | D9: 2794 | E9: 2447 | F9: 1243 | G9: 829 | H9: 879 | I9: 98 | J9: 2349 | K9: 61 | L9: 1182 | M9: 1 | N9: 828 | O9: 2630 | P9: 22 | Q9: 0.002227391
A10: 8 | B10: BST | C10: 8192 | D10: 2906 | E10: 2483 | F10: 1223 | G10: 759 | H10: 821 | I10: 111 | J10: 2372 | K10: 42 | L10: 1181 | M10: 0 | N10: 759 | O10: 2739 | P10: 24 | Q10: 0.002548598
A11: 9 | B11: BST | C11: 8192 | D11: 2820 | E11: 2445 | F11: 1248 | G11: 817 | H11: 862 | I11: 98 | J11: 2347 | K11: 53 | L11: 1195 | M11: 1 | N11: 816 | O11: 2664 | P11: 24 | Q11: 0.002393567
A12: 10 | B12: BST | C12: 8192 | D12: 2880 | E12: 2445 | F12: 1265 | G12: 787 | H12: 815 | I12: 91 | J12: 2354 | K12: 60 | L12: 1205 | M12: 0 | N12: 787 | O12: 2714 | P12: 27 | Q12: 0.002474757
A13: 11 | B13: BST | C13: 8192 | D13: 2895 | E13: 2462 | F13: 1279 | G13: 772 | H13: 784 | I13: 99 | J13: 2363 | K13: 52 | L13: 1227 | M13: 0 | N13: 772 | O13: 2744 | P13: 23 | Q13: 0.002539063
A14: 12 | B14: BST | C14: 8192 | D14: 2950 | E14: 2396 | F14: 1188 | G14: 816 | H14: 842 | I14: 103 | J14: 2293 | K14: 42 | L14: 1146 | M14: 0 | N14: 816 | O14: 2784 | P14: 24 | Q14: 0.002301821
... A62: 30 | B62: RedBlackBST | C62: 8192 | D62: 2903 | E62: 2457 | F62: 1193 | G62: 835 | H62: 804 | I62: 114 | J62: 2343 | K62: 41 | L62: 1152 | M62: 0 | N62: 835 | O62: 2766 | P62: 14 | Q62: 0.002287131
A65: Estadísticas
A66: Métrica | B66: BST | C66: RedBlackBST
A67: Mínimo (s) | B67: =MIN(Q3:Q32) -> 0.002216555 | C67: =MIN(Q33:Q62) -> 0.002270735
A68: Máximo (s) | B68: =MAX(Q3:Q32) -> 0.002635776 | C68: =MAX(Q33:Q62) -> 0.003410274
A69: Promedio (s) | B69: =AVERAGE(Q3:Q32) -> 0.0023994776 | C69: =AVERAGE(Q33:Q62) -> 0.0025812193
A70: Desv. Estándar | B70: =STDEV(Q3:Q32) -> 0.00011199702 | C70: =STDEV(Q33:Q62) -> 0.00019752301
A71: Coef. Variación | B71: =B70/B69 -> 0.046675585 | C71: =C70/C69 -> 0.07652314
A72: Altura Promedio | B72: =AVERAGE(P3:P32) -> 23.566667 | C72: =AVERAGE(P33:P62) -> 14.7
A73: Altura Máxima | B73: =MAX(P3:P32) -> 27 | C73: =MAX(P33:P62) -> 15
A76: Histograma — BST | B76: Frecuencia
A77: 0.0017440–0.0019068 | B77: 5
A78: 0.0019068–0.0020696 | B78: 5
A79: 0.0020696–0.0022324 | B79: 10
A80: 0.0022324–0.0023952 | B80: 7
A81: 0.0023952–0.0025580 | B81: 1
A82: 0.0025580–0.0027208 | B82: 1
A83: 0.0027208–0.0028836 | B83: 1
A86: Histograma — RedBlackBST | B86: Frecuencia
A87: 0.0018671–0.0020208 | B87: 4
A88: 0.0020208–0.0021745 | B88: 7
A89: 0.0021745–0.0023281 | B89: 4
A90: 0.0023281–0.0024818 | B90: 9
A91: 0.0024818–0.0026355 | B91: 3
A92: 0.0026355–0.0027892 | B92: 2
A93: 0.0027892–0.0029428 | B93: 1

Sheet Inv_16384
A1: Experimento de Inventario — m = 16384
A2: instancia | B2: estructura | C2: m | D2: purchase_total | E2: query_total | F2: lend_total | G2: receive_total | H2: dispose_total | I2: query_successful | J2: query_failed | K2: lend_successful | L2: lend_failed | M2: receive_successful | N2: receive_failed | O2: final_size | P2: final_height | Q2: elapsed_seconds
A3: 1 | B3: BST | C3: 16384 | D3: 5702 | E3: 4929 | F3: 2449 | G3: 1656 | H3: 1648 | I3: 213 | J3: 4716 | K3: 105 | L3: 2344 | M3: 0 | N3: 1656 | O3: 5393 | P3: 31 | Q3: 0.005879292
A4: 2 | B4: BST | C4: 16384 | D4: 5753 | E4: 4810 | F4: 2540 | G4: 1600 | H4: 1681 | I4: 220 | J4: 4590 | K4: 97 | L4: 2443 | M4: 1 | N4: 1599 | O4: 5440 | P4: 31 | Q4: 0.004779522
A5: 3 | B5: BST | C5: 16384 | D5: 5764 | E5: 4866 | F5: 2374 | G5: 1685 | H5: 1695 | I5: 201 | J5: 4665 | K5: 98 | L5: 2276 | M5: 0 | N5: 1685 | O5: 5448 | P5: 29 | Q5: 0.004735537
A6: 4 | B6: BST | C6: 16384 | D6: 5705 | E6: 4878 | F6: 2491 | G6: 1631 | H6: 1679 | I6: 183 | J6: 4695 | K6: 93 | L6: 2398 | M6: 0 | N6: 1631 | O6: 5405 | P6: 27 | Q6: 0.004658704
A7: 5 | B7: BST | C7: 16384 | D7: 5609 | E7: 4965 | F7: 2484 | G7: 1653 | H7: 1673 | I7: 216 | J7: 4749 | K7: 92 | L7: 2392 | M7: 0 | N7: 1653 | O7: 5334 | P7: 29 | Q7: 0.00440706
A8: 6 | B8: BST | C8: 16384 | D8: 5737 | E8: 4948 | F8: 2411 | G8: 1635 | H8: 1653 | I8: 216 | J8: 4732 | K8: 94 | L8: 2317 | M8: 1 | N8: 1634 | O8: 5430 | P8: 28 | Q8: 0.004430225
A9: 7 | B9: BST | C9: 16384 | D9: 5861 | E9: 4799 | F9: 2436 | G9: 1636 | H9: 1652 | I9: 200 | J9: 4599 | K9: 78 | L9: 2358 | M9: 1 | N9: 1635 | O9: 5561 | P9: 26 | Q9: 0.004788196
A10: 8 | B10: BST | C10: 16384 | D10: 5793 | E10: 4846 | F10: 2431 | G10: 1638 | H10: 1676 | I10: 217 | J10: 4629 | K10: 89 | L10: 2342 | M10: 1 | N10: 1637 | O10: 5503 | P10: 29 | Q10: 0.004921633
A11: 9 | B11: BST | C11: 16384 | D11: 5736 | E11: 4904 | F11: 2494 | G11: 1662 | H11: 1588 | I11: 221 | J11: 4683 | K11: 90 | L11: 2404 | M11: 0 | N11: 1662 | O11: 5454 | P11: 27 | Q11: 0.004992878
A12: 10 | B12: BST | C12: 16384 | D12: 5767 | E12: 4888 | F12: 2473 | G12: 1696 | H12: 1560 | I12: 207 | J12: 4681 | K12: 98 | L12: 2375 | M12: 0 | N12: 1696 | O12: 5447 | P12: 25 | Q12: 0.004618074
A13: 11 | B13: BST | C13: 16384 | D13: 5753 | E13: 4954 | F13: 2499 | G13: 1620 | H13: 1558 | I13: 211 | J13: 4743 | K13: 92 | L13: 2407 | M13: 0 | N13: 1620 | O13: 5444 | P13: 25 | Q13: 0.004615268
A14: 12 | B14: BST | C14: 16384 | D14: 5696 | E14: 4880 | F14: 2503 | G14: 1640 | H14: 1665 | I14: 219 | J14: 4661 | K14: 98 | L14: 2405 | M14: 1 | N14: 1639 | O14: 5404 | P14: 30 | Q14: 0.004378628
... A62: 30 | B62: RedBlackBST | C62: 16384 | D62: 5669 | E62: 4915 | F62: 2506 | G62: 1660 | H62: 1634 | I62: 198 | J62: 4717 | K62: 111 | L62: 2395 | M62: 0 | N62: 1660 | O62: 5359 | P62: 17 | Q62: 0.004842946
A65: Estadísticas
A66: Métrica | B66: BST | C66: RedBlackBST
A67: Mínimo (s) | B67: =MIN(Q3:Q32) -> 0.004019437 | C67: =MIN(Q33:Q62) -> 0.004264461
A68: Máximo (s) | B68: =MAX(Q3:Q32) -> 0.005879292 | C68: =MAX(Q33:Q62) -> 0.005989356
A69: Promedio (s) | B69: =AVERAGE(Q3:Q32) -> 0.0045460771 | C69: =AVERAGE(Q33:Q62) -> 0.0047395519
A70: Desv. Estándar | B70: =STDEV(Q3:Q32) -> 0.00034131865 | C70: =STDEV(Q33:Q62) -> 0.00033892961
A71: Coef. Variación | B71: =B70/B69 -> 0.07507982 | C71: =C70/C69 -> 0.071510899
A72: Altura Promedio | B72: =AVERAGE(P3:P32) -> 27.8 | C72: =AVERAGE(P33:P62) -> 16.033333
A73: Altura Máxima | B73: =MAX(P3:P32) -> 31 | C73: =MAX(P33:P62) -> 17
A76: Histograma — BST | B76: Frecuencia
A77: 0.0040622–0.0045550 | B77: 13
A78: 0.0045550–0.0050478 | B78: 7
A79: 0.0050478–0.0055406 | B79: 3
A80: 0.0055406–0.0060333 | B80: 0
A81: 0.0060333–0.0065261 | B81: 0
A82: 0.0065261–0.0070189 | B82: 3
A83: 0.0070189–0.0075117 | B83: 4
A86: Histograma — RedBlackBST | B86: Frecuencia
A87: 0.0042141–0.0047312 | B87: 7
A88: 0.0047312–0.0052483 | B88: 11
A89: 0.0052483–0.0057653 | B89: 3
A90: 0.0057653–0.0062824 | B90: 0
A91: 0.0062824–0.0067995 | B91: 0
A92: 0.0067995–0.0073166 | B92: 5
A93: 0.0073166–0.0078336 | B93: 4

Sheet Inv_32768
A1: Experimento de Inventario — m = 32768
A2: instancia | B2: estructura | C2: m | D2: purchase_total | E2: query_total | F2: lend_total | G2: receive_total | H2: dispose_total | I2: query_successful | J2: query_failed | K2: lend_successful | L2: lend_failed | M2: receive_successful | N2: receive_failed | O2: final_size | P2: final_height | Q2: elapsed_seconds
A3: 1 | B3: BST | C3: 32768 | D3: 11525 | E3: 9770 | F3: 4998 | G3: 3237 | H3: 3238 | I3: 395 | J3: 9375 | K3: 203 | L3: 4795 | M3: 0 | N3: 3237 | O3: 10878 | P3: 29 | Q3: 0.011562143
A4: 2 | B4: BST | C4: 32768 | D4: 11362 | E4: 9894 | F4: 4826 | G4: 3313 | H4: 3373 | I4: 437 | J4: 9457 | K4: 202 | L4: 4624 | M4: 2 | N4: 3311 | O4: 10737 | P4: 28 | Q4: 0.010903117
A5: 3 | B5: BST | C5: 32768 | D5: 11469 | E5: 9849 | F5: 4893 | G5: 3258 | H5: 3299 | I5: 415 | J5: 9434 | K5: 201 | L5: 4692 | M5: 1 | N5: 3257 | O5: 10843 | P5: 30 | Q5: 0.010575982
A6: 4 | B6: BST | C6: 32768 | D6: 11353 | E6: 9888 | F6: 4923 | G6: 3282 | H6: 3322 | I6: 431 | J6: 9457 | K6: 180 | L6: 4743 | M6: 2 | N6: 3280 | O6: 10747 | P6: 32 | Q6: 0.010377048
A7: 5 | B7: BST | C7: 32768 | D7: 11314 | E7: 10062 | F7: 4795 | G7: 3252 | H7: 3345 | I7: 419 | J7: 9643 | K7: 179 | L7: 4616 | M7: 2 | N7: 3250 | O7: 10665 | P7: 31 | Q7: 0.010684985
A8: 6 | B8: BST | C8: 32768 | D8: 11432 | E8: 9838 | F8: 4964 | G8: 3274 | H8: 3260 | I8: 431 | J8: 9407 | K8: 171 | L8: 4793 | M8: 0 | N8: 3274 | O8: 10800 | P8: 27 | Q8: 0.010624555
A9: 7 | B9: BST | C9: 32768 | D9: 11571 | E9: 9864 | F9: 4820 | G9: 3190 | H9: 3323 | I9: 406 | J9: 9458 | K9: 199 | L9: 4621 | M9: 2 | N9: 3188 | O9: 10942 | P9: 29 | Q9: 0.008565063
A10: 8 | B10: BST | C10: 32768 | D10: 11335 | E10: 9789 | F10: 4957 | G10: 3343 | H10: 3344 | I10: 405 | J10: 9384 | K10: 183 | L10: 4774 | M10: 2 | N10: 3341 | O10: 10751 | P10: 28 | Q10: 0.008708475
A11: 9 | B11: BST | C11: 32768 | D11: 11461 | E11: 9809 | F11: 4864 | G11: 3319 | H11: 3315 | I11: 393 | J11: 9416 | K11: 175 | L11: 4689 | M11: 1 | N11: 3318 | O11: 10852 | P11: 27 | Q11: 0.008915912
A12: 10 | B12: BST | C12: 32768 | D12: 11515 | E12: 9871 | F12: 4892 | G12: 3249 | H12: 3241 | I12: 416 | J12: 9455 | K12: 189 | L12: 4703 | M12: 3 | N12: 3246 | O12: 10898 | P12: 30 | Q12: 0.00831373
A13: 11 | B13: BST | C13: 32768 | D13: 11413 | E13: 9858 | F13: 4864 | G13: 3283 | H13: 3350 | I13: 405 | J13: 9453 | K13: 179 | L13: 4685 | M13: 0 | N13: 3283 | O13: 10805 | P13: 32 | Q13: 0.008507947
A14: 12 | B14: BST | C14: 32768 | D14: 11459 | E14: 9781 | F14: 4951 | G14: 3341 | H14: 3236 | I14: 411 | J14: 9370 | K14: 180 | L14: 4771 | M14: 4 | N14: 3337 | O14: 10837 | P14: 31 | Q14: 0.008914631
... A62: 30 | B62: RedBlackBST | C62: 32768 | D62: 11313 | E62: 9975 | F62: 4925 | G62: 3275 | H62: 3280 | I62: 418 | J62: 9557 | K62: 190 | L62: 4735 | M62: 1 | N62: 3274 | O62: 10677 | P62: 18 | Q62: 0.009749899
A65: Estadísticas
A66: Métrica | B66: BST | C66: RedBlackBST
A67: Mínimo (s) | B67: =MIN(Q3:Q32) -> 0.00831373 | C67: =MIN(Q33:Q62) -> 0.007383211
A68: Máximo (s) | B68: =MAX(Q3:Q32) -> 0.012028155 | C68: =MAX(Q33:Q62) -> 0.011582186
A69: Promedio (s) | B69: =AVERAGE(Q3:Q32) -> 0.0098798765 | C69: =AVERAGE(Q33:Q62) -> 0.0094746326
A70: Desv. Estándar | B70: =STDEV(Q3:Q32) -> 0.001143344 | C70: =STDEV(Q33:Q62) -> 0.0012629518
A71: Coef. Variación | B71: =B70/B69 -> 0.11572453 | C71: =C70/C69 -> 0.13329823
A72: Altura Promedio | B72: =AVERAGE(P3:P32) -> 30.166667 | C72: =AVERAGE(P33:P62) -> 17.566667
A73: Altura Máxima | B73: =MAX(P3:P32) -> 35 | C73: =MAX(P33:P62) -> 19
A76: Histograma — BST | B76: Frecuencia
A77: 0.0078507–0.0083710 | B77: 3
A78: 0.0083710–0.0088914 | B78: 2
A79: 0.0088914–0.0094117 | B79: 3
A80: 0.0094117–0.0099320 | B80: 14
A81: 0.0099320–0.0104524 | B81: 6
A82: 0.0104524–0.0109727 | B82: 0
A83: 0.0109727–0.0114930 | B83: 2
A86: Histograma — RedBlackBST | B86: Frecuencia
A87: 0.0071087–0.0077037 | B87: 2
A88: 0.0077037–0.0082987 | B88: 4
A89: 0.0082987–0.0088937 | B89: 1
A90: 0.0088937–0.0094887 | B90: 4
A91: 0.0094887–0.0100837 | B91: 9
A92: 0.0100837–0.0106787 | B92: 7
A93: 0.0106787–0.0112738 | B93: 3

Sheet Inv_65536
A1: Experimento de Inventario — m = 65536
A2: instancia | B2: estructura | C2: m | D2: purchase_total | E2: query_total | F2: lend_total | G2: receive_total | H2: dispose_total | I2: query_successful | J2: query_failed | K2: lend_successful | L2: lend_failed | M2: receive_successful | N2: receive_failed | O2: final_size | P2: final_height | Q2: elapsed_seconds
A3: 1 | B3: BST | C3: 65536 | D3: 22978 | E3: 19799 | F3: 9685 | G3: 6583 | H3: 6491 | I3: 828 | J3: 18971 | K3: 365 | L3: 9320 | M3: 2 | N3: 6581 | O3: 21728 | P3: 31 | Q3: 0.021061341
A4: 2 | B4: BST | C4: 65536 | D4: 22926 | E4: 19794 | F4: 9813 | G4: 6495 | H4: 6508 | I4: 807 | J4: 18987 | K4: 381 | L4: 9432 | M4: 3 | N4: 6492 | O4: 21681 | P4: 33 | Q4: 0.020401483
A5: 3 | B5: BST | C5: 65536 | D5: 22904 | E5: 19811 | F5: 9767 | G5: 6560 | H5: 6494 | I5: 850 | J5: 18961 | K5: 343 | L5: 9424 | M5: 2 | N5: 6558 | O5: 21679 | P5: 34 | Q5: 0.01986561
A6: 4 | B6: BST | C6: 65536 | D6: 22757 | E6: 19674 | F6: 9961 | G6: 6657 | H6: 6487 | I6: 829 | J6: 18845 | K6: 381 | L6: 9580 | M6: 0 | N6: 6657 | O6: 21499 | P6: 31 | Q6: 0.022338905
A7: 5 | B7: BST | C7: 65536 | D7: 22956 | E7: 19518 | F7: 9822 | G7: 6606 | H7: 6634 | I7: 888 | J7: 18630 | K7: 381 | L7: 9441 | M7: 1 | N7: 6605 | O7: 21685 | P7: 34 | Q7: 0.021855109
A8: 6 | B8: BST | C8: 65536 | D8: 22957 | E8: 19704 | F8: 9839 | G8: 6488 | H8: 6548 | I8: 780 | J8: 18924 | K8: 380 | L8: 9459 | M8: 2 | N8: 6486 | O8: 21757 | P8: 31 | Q8: 0.020487542
A9: 7 | B9: BST | C9: 65536 | D9: 22970 | E9: 19577 | F9: 9863 | G9: 6631 | H9: 6495 | I9: 846 | J9: 18731 | K9: 402 | L9: 9461 | M9: 1 | N9: 6630 | O9: 21730 | P9: 32 | Q9: 0.023600884
A10: 8 | B10: BST | C10: 65536 | D10: 22771 | E10: 19613 | F10: 9827 | G10: 6550 | H10: 6775 | I10: 866 | J10: 18747 | K10: 385 | L10: 9442 | M10: 2 | N10: 6548 | O10: 21545 | P10: 37 | Q10: 0.022277491
A11: 9 | B11: BST | C11: 65536 | D11: 23112 | E11: 19542 | F11: 9785 | G11: 6540 | H11: 6557 | I11: 849 | J11: 18693 | K11: 343 | L11: 9442 | M11: 1 | N11: 6539 | O11: 21821 | P11: 34 | Q11: 0.025331429
A12: 10 | B12: BST | C12: 65536 | D12: 22774 | E12: 19832 | F12: 9804 | G12: 6656 | H12: 6470 | I12: 772 | J12: 19060 | K12: 358 | L12: 9446 | M12: 1 | N12: 6655 | O12: 21570 | P12: 30 | Q12: 0.024755727
A13: 11 | B13: BST | C13: 65536 | D13: 22825 | E13: 19535 | F13: 9854 | G13: 6731 | H13: 6591 | I13: 855 | J13: 18680 | K13: 381 | L13: 9473 | M13: 1 | N13: 6730 | O13: 21617 | P13: 30 | Q13: 0.028230265
A14: 12 | B14: BST | C14: 65536 | D14: 22872 | E14: 19506 | F14: 9913 | G14: 6634 | H14: 6611 | I14: 820 | J14: 18686 | K14: 352 | L14: 9561 | M14: 1 | N14: 6633 | O14: 21649 | P14: 35 | Q14: 0.019095518
... A62: 30 | B62: RedBlackBST | C62: 65536 | D62: 22913 | E62: 19692 | F62: 9829 | G62: 6574 | H62: 6528 | I62: 790 | J62: 18902 | K62: 371 | L62: 9458 | M62: 1 | N62: 6573 | O62: 21647 | P62: 19 | Q62: 0.023487607
A65: Estadísticas
A66: Métrica | B66: BST | C66: RedBlackBST
A67: Mínimo (s) | B67: =MIN(Q3:Q32) -> 0.018608897 | C67: =MIN(Q33:Q62) -> 0.01870532
A68: Máximo (s) | B68: =MAX(Q3:Q32) -> 0.02973936 | C68: =MAX(Q33:Q62) -> 0.028895317
A69: Promedio (s) | B69: =AVERAGE(Q3:Q32) -> 0.022522212 | C69: =AVERAGE(Q33:Q62) -> 0.021981787
A70: Desv. Estándar | B70: =STDEV(Q3:Q32) -> 0.0029135375 | C70: =STDEV(Q33:Q62) -> 0.002751945
A71: Coef. Variación | B71: =B70/B69 -> 0.12936285 | C71: =C70/C69 -> 0.12519205
A72: Altura Promedio | B72: =AVERAGE(P3:P32) -> 32.833333 | C72: =AVERAGE(P33:P62) -> 19.2
A73: Altura Máxima | B73: =MAX(P3:P32) -> 37 | C73: =MAX(P33:P62) -> 20
A76: Histograma — BST | B76: Frecuencia
A77: 0.0167344–0.0188618 | B77: 7
A78: 0.0188618–0.0209892 | B78: 12
A79: 0.0209892–0.0231166 | B79: 5
A80: 0.0231166–0.0252441 | B80: 3
A81: 0.0252441–0.0273715 | B81: 2
A82: 0.0273715–0.0294989 | B82: 0
A83: 0.0294989–0.0316263 | B83: 1
A86: Histograma — RedBlackBST | B86: Frecuencia
A87: 0.0161999–0.0175366 | B87: 10
A88: 0.0175366–0.0188734 | B88: 8
A89: 0.0188734–0.0202101 | B89: 1
A90: 0.0202101–0.0215468 | B90: 4
A91: 0.0215468–0.0228836 | B91: 2
A92: 0.0228836–0.0242203 | B92: 2
A93: 0.0242203–0.0255570 | B93: 3

Sheet Inv_131072
A1: Experimento de Inventario — m = 131072
A2: instancia | B2: estructura | C2: m | D2: purchase_total | E2: query_total | F2: lend_total | G2: receive_total | H2: dispose_total | I2: query_successful | J2: query_failed | K2: lend_successful | L2: lend_failed | M2: receive_successful | N2: receive_failed | O2: final_size | P2: final_height | Q2: elapsed_seconds
A3: 1 | B3: BST | C3: 131072 | D3: 45766 | E3: 39294 | F3: 19731 | G3: 13170 | H3: 13111 | I3: 1619 | J3: 37675 | K3: 730 | L3: 19001 | M3: 4 | N3: 13166 | O3: 43224 | P3: 36 | Q3: 0.071154764
A4: 2 | B4: BST | C4: 131072 | D4: 45544 | E4: 39524 | F4: 19818 | G4: 13081 | H4: 13105 | I4: 1661 | J4: 37863 | K4: 769 | L4: 19049 | M4: 2 | N4: 13079 | O4: 43121 | P4: 39 | Q4: 0.05195262
A5: 3 | B5: BST | C5: 131072 | D5: 45801 | E5: 39342 | F5: 19569 | G5: 13063 | H5: 13297 | I5: 1677 | J5: 37665 | K5: 735 | L5: 18834 | M5: 2 | N5: 13061 | O5: 43299 | P5: 32 | Q5: 0.057236751
A6: 4 | B6: BST | C6: 131072 | D6: 45798 | E6: 39414 | F6: 19601 | G6: 13195 | H6: 13064 | I6: 1659 | J6: 37755 | K6: 727 | L6: 18874 | M6: 4 | N6: 13191 | O6: 43342 | P6: 34 | Q6: 0.047514953
A7: 5 | B7: BST | C7: 131072 | D7: 45728 | E7: 39490 | F7: 19631 | G7: 12975 | H7: 13248 | I7: 1623 | J7: 37867 | K7: 745 | L7: 18886 | M7: 4 | N7: 12971 | O7: 43236 | P7: 36 | Q7: 0.050362183
A8: 6 | B8: BST | C8: 131072 | D8: 45919 | E8: 39443 | F8: 19500 | G8: 13034 | H8: 13176 | I8: 1606 | J8: 37837 | K8: 823 | L8: 18677 | M8: 1 | N8: 13033 | O8: 43503 | P8: 36 | Q8: 0.051912197
A9: 7 | B9: BST | C9: 131072 | D9: 45721 | E9: 39467 | F9: 19608 | G9: 13021 | H9: 13255 | I9: 1628 | J9: 37839 | K9: 757 | L9: 18851 | M9: 5 | N9: 13016 | O9: 43284 | P9: 40 | Q9: 0.049697178
A10: 8 | B10: BST | C10: 131072 | D10: 45817 | E10: 38953 | F10: 19733 | G10: 13284 | H10: 13285 | I10: 1706 | J10: 37247 | K10: 773 | L10: 18960 | M10: 5 | N10: 13279 | O10: 43354 | P10: 36 | Q10: 0.061782397
A11: 9 | B11: BST | C11: 131072 | D11: 45835 | E11: 39392 | F11: 19685 | G11: 13118 | H11: 13042 | I11: 1700 | J11: 37692 | K11: 812 | L11: 18873 | M11: 3 | N11: 13115 | O11: 43387 | P11: 36 | Q11: 0.060419221
A12: 10 | B12: BST | C12: 131072 | D12: 46022 | E12: 39114 | F12: 19478 | G12: 13206 | H12: 13252 | I12: 1579 | J12: 37535 | K12: 708 | L12: 18770 | M12: 4 | N12: 13202 | O12: 43510 | P12: 36 | Q12: 0.055796135
A13: 11 | B13: BST | C13: 131072 | D13: 45834 | E13: 39215 | F13: 19861 | G13: 13216 | H13: 12946 | I13: 1563 | J13: 37652 | K13: 728 | L13: 19133 | M13: 2 | N13: 13214 | O13: 43339 | P13: 37 | Q13: 0.058923129
A14: 12 | B14: BST | C14: 131072 | D14: 46132 | E14: 38975 | F14: 19834 | G14: 13134 | H14: 12997 | I14: 1676 | J14: 37299 | K14: 801 | L14: 19033 | M14: 7 | N14: 13127 | O14: 43670 | P14: 33 | Q14: 0.06362907
... A62: 30 | B62: RedBlackBST | C62: 131072 | D62: 45807 | E62: 39238 | F62: 19594 | G62: 13252 | H62: 13181 | I62: 1649 | J62: 37589 | K62: 729 | L62: 18865 | M62: 0 | N62: 13252 | O62: 43331 | P62: 21 | Q62: 0.047928616
A65: Estadísticas
A66: Métrica | B66: BST | C66: RedBlackBST
A67: Mínimo (s) | B67: =MIN(Q3:Q32) -> 0.043921618 | C67: =MIN(Q33:Q62) -> 0.044022839
A68: Máximo (s) | B68: =MAX(Q3:Q32) -> 0.071154764 | C68: =MAX(Q33:Q62) -> 0.066766455
A69: Promedio (s) | B69: =AVERAGE(Q3:Q32) -> 0.054662437 | C69: =AVERAGE(Q33:Q62) -> 0.052242052
A70: Desv. Estándar | B70: =STDEV(Q3:Q32) -> 0.0068304059 | C70: =STDEV(Q33:Q62) -> 0.0058699844
A71: Coef. Variación | B71: =B70/B69 -> 0.12495612 | C71: =C70/C69 -> 0.11236129
A72: Altura Promedio | B72: =AVERAGE(P3:P32) -> 36.233333 | C72: =AVERAGE(P33:P62) -> 20.533333
A73: Altura Máxima | B73: =MAX(P3:P32) -> 40 | C73: =MAX(P33:P62) -> 21
A76: Histograma — BST | B76: Frecuencia
A77: 0.0402135–0.0429489 | B77: 5
A78: 0.0429489–0.0456843 | B78: 10
A79: 0.0456843–0.0484196 | B79: 5
A80: 0.0484196–0.0511550 | B80: 4
A81: 0.0511550–0.0538904 | B81: 2
A82: 0.0538904–0.0566258 | B82: 2
A83: 0.0566258–0.0593612 | B83: 2
A86: Histograma — RedBlackBST | B86: Frecuencia
A87: 0.0383893–0.0414670 | B87: 2
A88: 0.0414670–0.0445447 | B88: 12
A89: 0.0445447–0.0476224 | B89: 5
A90: 0.0476224–0.0507001 | B90: 5
A91: 0.0507001–0.0537778 | B91: 3
A92: 0.0537778–0.0568554 | B92: 2
A93: 0.0568554–0.0599331 | B93: 1

Sheet Inv_262144
A1: Experimento de Inventario — m = 262144
A2: instancia | B2: estructura | C2: m | D2: purchase_total | E2: query_total | F2: lend_total | G2: receive_total | H2: dispose_total | I2: query_successful | J2: query_failed | K2: lend_successful | L2: lend_failed | M2: receive_successful | N2: receive_failed | O2: final_size | P2: final_height | Q2: elapsed_seconds
A3: 1 | B3: BST | C3: 262144 | D3: 92151 | E3: 78543 | F3: 39193 | G3: 25932 | H3: 26325 | I3: 3263 | J3: 75280 | K3: 1519 | L3: 37674 | M3: 7 | N3: 25925 | O3: 87138 | P3: 39 | Q3: 0.14264113
A4: 2 | B4: BST | C4: 262144 | D4: 91583 | E4: 79031 | F4: 39521 | G4: 26051 | H4: 25958 | I4: 3423 | J4: 75608 | K4: 1546 | L4: 37975 | M4: 7 | N4: 26044 | O4: 86681 | P4: 40 | Q4: 0.11818768
A5: 3 | B5: BST | C5: 262144 | D5: 91930 | E5: 78687 | F5: 39141 | G5: 26355 | H5: 26031 | I5: 3332 | J5: 75355 | K5: 1555 | L5: 37586 | M5: 9 | N5: 26346 | O5: 86934 | P5: 39 | Q5: 0.11810723
A6: 4 | B6: BST | C6: 262144 | D6: 91806 | E6: 78579 | F6: 38859 | G6: 26413 | H6: 26487 | I6: 3305 | J6: 75274 | K6: 1483 | L6: 37376 | M6: 10 | N6: 26403 | O6: 86826 | P6: 46 | Q6: 0.13642689
A7: 5 | B7: BST | C7: 262144 | D7: 91650 | E7: 78879 | F7: 39253 | G7: 26352 | H7: 26010 | I7: 3340 | J7: 75539 | K7: 1531 | L7: 37722 | M7: 11 | N7: 26341 | O7: 86820 | P7: 39 | Q7: 0.124146
A8: 6 | B8: BST | C8: 262144 | D8: 92014 | E8: 78355 | F8: 39359 | G8: 26410 | H8: 26006 | I8: 3322 | J8: 75033 | K8: 1540 | L8: 37819 | M8: 3 | N8: 26407 | O8: 87027 | P8: 38 | Q8: 0.14120097
A9: 7 | B9: BST | C9: 262144 | D9: 91403 | E9: 78729 | F9: 39261 | G9: 26286 | H9: 26465 | I9: 3310 | J9: 75419 | K9: 1494 | L9: 37767 | M9: 3 | N9: 26283 | O9: 86407 | P9: 40 | Q9: 0.12223423
A10: 8 | B10: BST | C10: 262144 | D10: 91621 | E10: 78388 | F10: 39419 | G10: 26390 | H10: 26326 | I10: 3282 | J10: 75106 | K10: 1495 | L10: 37924 | M10: 6 | N10: 26384 | O10: 86642 | P10: 37 | Q10: 0.12590646
A11: 9 | B11: BST | C11: 262144 | D11: 91740 | E11: 78509 | F11: 39237 | G11: 26292 | H11: 26366 | I11: 3338 | J11: 75171 | K11: 1522 | L11: 37715 | M11: 6 | N11: 26286 | O11: 86703 | P11: 40 | Q11: 0.10927133
A12: 10 | B12: BST | C12: 262144 | D12: 91715 | E12: 78891 | F12: 39331 | G12: 26127 | H12: 26080 | I12: 3328 | J12: 75563 | K12: 1535 | L12: 37796 | M12: 2 | N12: 26125 | O12: 86874 | P12: 38 | Q12: 0.14907329
A13: 11 | B13: BST | C13: 262144 | D13: 91865 | E13: 78376 | F13: 39277 | G13: 26371 | H13: 26255 | I13: 3255 | J13: 75121 | K13: 1512 | L13: 37765 | M13: 4 | N13: 26367 | O13: 86838 | P13: 38 | Q13: 0.15031615
A14: 12 | B14: BST | C14: 262144 | D14: 91680 | E14: 78726 | F14: 39464 | G14: 26144 | H14: 26130 | I14: 3332 | J14: 75394 | K14: 1542 | L14: 37922 | M14: 9 | N14: 26135 | O14: 86836 | P14: 41 | Q14: 0.13241677
... A62: 30 | B62: RedBlackBST | C62: 262144 | D62: 91708 | E62: 78537 | F62: 39656 | G62: 26090 | H62: 26153 | I62: 3226 | J62: 75311 | K62: 1504 | L62: 38152 | M62: 6 | N62: 26084 | O62: 86735 | P62: 21 | Q62: 0.12191464
A65: Estadísticas
A66: Métrica | B66: BST | C66: RedBlackBST
A67: Mínimo (s) | B67: =MIN(Q3:Q32) -> 0.10927133 | C67: =MIN(Q33:Q62) -> 0.11069671
A68: Máximo (s) | B68: =MAX(Q3:Q32) -> 0.17855419 | C68: =MAX(Q33:Q62) -> 0.17514326
A69: Promedio (s) | B69: =AVERAGE(Q3:Q32) -> 0.13323365 | C69: =AVERAGE(Q33:Q62) -> 0.13174957
A70: Desv. Estándar | B70: =STDEV(Q3:Q32) -> 0.013581478 | C70: =STDEV(Q33:Q62) -> 0.013792622
A71: Coef. Variación | B71: =B70/B69 -> 0.1019373 | C71: =C70/C69 -> 0.10468818
A72: Altura Promedio | B72: =AVERAGE(P3:P32) -> 38.933333 | C72: =AVERAGE(P33:P62) -> 22.033333
A73: Altura Máxima | B73: =MAX(P3:P32) -> 46 | C73: =MAX(P33:P62) -> 24
A76: Histograma — BST | B76: Frecuencia
A77: 0.1085374–0.1196570 | B77: 7
A78: 0.1196570–0.1307766 | B78: 8
A79: 0.1307766–0.1418962 | B79: 9
A80: 0.1418962–0.1530157 | B80: 1
A81: 0.1530157–0.1641353 | B81: 2
A82: 0.1641353–0.1752549 | B82: 1
A83: 0.1752549–0.1863745 | B83: 2
A86: Histograma — RedBlackBST | B86: Frecuencia
A87: 0.1012981–0.1088555 | B87: 7
A88: 0.1088555–0.1164129 | B88: 9
A89: 0.1164129–0.1239703 | B89: 6
A90: 0.1239703–0.1315277 | B90: 2
A91: 0.1315277–0.1390852 | B91: 3
A92: 0.1390852–0.1466426 | B92: 2
A93: 0.1466426–0.1542000 | B93: 1

Sheet Inv_524288
A1: Experimento de Inventario — m = 524288
A2: instancia | B2: estructura | C2: m | D2: purchase_total | E2: query_total | F2: lend_total | G2: receive_total | H2: dispose_total | I2: query_successful | J2: query_failed | K2: lend_successful | L2: lend_failed | M2: receive_successful | N2: receive_failed | O2: final_size | P2: final_height | Q2: elapsed_seconds
A3: 1 | B3: BST | C3: 524288 | D3: 183569 | E3: 157154 | F3: 78614 | G3: 52619 | H3: 52332 | I3: 6550 | J3: 150604 | K3: 3007 | L3: 75607 | M3: 16 | N3: 52603 | O3: 173715 | P3: 39 | Q3: 0.34303832
A4: 2 | B4: BST | C4: 524288 | D4: 184246 | E4: 156926 | F4: 78384 | G4: 51990 | H4: 52742 | I4: 6595 | J4: 150331 | K4: 2981 | L4: 75403 | M4: 16 | N4: 51974 | O4: 174197 | P4: 43 | Q4: 0.3850413
A5: 3 | B5: BST | C5: 524288 | D5: 183649 | E5: 157034 | F5: 78917 | G5: 52464 | H5: 52224 | I5: 6684 | J5: 150350 | K5: 2877 | L5: 76040 | M5: 16 | N5: 52448 | O5: 173806 | P5: 40 | Q5: 0.36725994
A6: 4 | B6: BST | C6: 524288 | D6: 183248 | E6: 157239 | F6: 78674 | G6: 52707 | H6: 52420 | I6: 6498 | J6: 150741 | K6: 2890 | L6: 75784 | M6: 13 | N6: 52694 | O6: 173354 | P6: 43 | Q6: 0.36687497
A7: 5 | B7: BST | C7: 524288 | D7: 183052 | E7: 157684 | F7: 78508 | G7: 52376 | H7: 52668 | I7: 6499 | J7: 151185 | K7: 2987 | L7: 75521 | M7: 15 | N7: 52361 | O7: 173126 | P7: 42 | Q7: 0.262624
A8: 6 | B8: BST | C8: 524288 | D8: 183607 | E8: 157193 | F8: 78490 | G8: 52277 | H8: 52721 | I8: 6716 | J8: 150477 | K8: 3028 | L8: 75462 | M8: 15 | N8: 52262 | O8: 173682 | P8: 41 | Q8: 0.38172983
A9: 7 | B9: BST | C9: 524288 | D9: 183451 | E9: 157283 | F9: 78725 | G9: 52597 | H9: 52232 | I9: 6714 | J9: 150569 | K9: 3009 | L9: 75716 | M9: 14 | N9: 52583 | O9: 173605 | P9: 42 | Q9: 0.2644955
A10: 8 | B10: BST | C10: 524288 | D10: 183211 | E10: 157561 | F10: 78631 | G10: 52751 | H10: 52134 | I10: 6620 | J10: 150941 | K10: 3038 | L10: 75593 | M10: 10 | N10: 52741 | O10: 173365 | P10: 42 | Q10: 0.37438798
A11: 9 | B11: BST | C11: 524288 | D11: 183589 | E11: 157329 | F11: 78646 | G11: 52405 | H11: 52319 | I11: 6698 | J11: 150631 | K11: 2947 | L11: 75699 | M11: 16 | N11: 52389 | O11: 173720 | P11: 42 | Q11: 0.31573433
A12: 10 | B12: BST | C12: 524288 | D12: 183678 | E12: 157314 | F12: 78547 | G12: 52399 | H12: 52350 | I12: 6631 | J12: 150683 | K12: 2998 | L12: 75549 | M12: 13 | N12: 52386 | O12: 173622 | P12: 42 | Q12: 0.29466036
A13: 11 | B13: BST | C13: 524288 | D13: 183034 | E13: 157650 | F13: 78799 | G13: 52553 | H13: 52252 | I13: 6566 | J13: 151084 | K13: 2987 | L13: 75812 | M13: 18 | N13: 52535 | O13: 173143 | P13: 43 | Q13: 0.35892163
A14: 12 | B14: BST | C14: 524288 | D14: 183607 | E14: 157823 | F14: 77977 | G14: 52228 | H14: 52653 | I14: 6658 | J14: 151165 | K14: 2858 | L14: 75119 | M14: 8 | N14: 52220 | O14: 173650 | P14: 42 | Q14: 0.3240158
... A62: 30 | B62: RedBlackBST | C62: 524288 | D62: 183496 | E62: 157068 | F62: 78561 | G62: 52545 | H62: 52618 | I62: 6605 | J62: 150463 | K62: 3010 | L62: 75551 | M62: 16 | N62: 52529 | O62: 173402 | P62: 23 | Q62: 0.37353906
A65: Estadísticas
A66: Métrica | B66: BST | C66: RedBlackBST
A67: Mínimo (s) | B67: =MIN(Q3:Q32) -> 0.262624 | C67: =MIN(Q33:Q62) -> 0.28545945
A68: Máximo (s) | B68: =MAX(Q3:Q32) -> 0.3850413 | C68: =MAX(Q33:Q62) -> 0.40706534
A69: Promedio (s) | B69: =AVERAGE(Q3:Q32) -> 0.32775229 | C69: =AVERAGE(Q33:Q62) -> 0.33107444
A70: Desv. Estándar | B70: =STDEV(Q3:Q32) -> 0.037219649 | C70: =STDEV(Q33:Q62) -> 0.029002455
A71: Coef. Variación | B71: =B70/B69 -> 0.1135603 | C71: =C70/C69 -> 0.087601008
A72: Altura Promedio | B72: =AVERAGE(P3:P32) -> 41.133333 | C72: =AVERAGE(P33:P62) -> 23.466667
A73: Altura Máxima | B73: =MAX(P3:P32) -> 47 | C73: =MAX(P33:P62) -> 24
A76: Histograma — BST | B76: Frecuencia
A77: 0.2713191–0.3001649 | B77: 4
A78: 0.3001649–0.3290106 | B78: 3
A79: 0.3290106–0.3578563 | B79: 7
A80: 0.3578563–0.3867021 | B80: 5
A81: 0.3867021–0.4155478 | B81: 6
A82: 0.4155478–0.4443935 | B82: 1
A83: 0.4443935–0.4732393 | B83: 4
A86: Histograma — RedBlackBST | B86: Frecuencia
A87: 0.2398409–0.2624539 | B87: 2
A88: 0.2624539–0.2850669 | B88: 2
A89: 0.2850669–0.3076799 | B89: 5
A90: 0.3076799–0.3302929 | B90: 5
A91: 0.3302929–0.3529059 | B91: 8
A92: 0.3529059–0.3755188 | B92: 3
A93: 0.3755188–0.3981318 | B93: 5
